Workbook

Sheet players
A1: player_id | B1: player_name | C1: nba_team | D1: position | E1: pts | F1: trb | G1: ast | H1: stl | I1: blk | J1: three_p | K1: tov | L1: status | M1: fantasy_value
A2: 1 | B2: Nikola Jokić | D2: C | E2: 27.7 | F2: 12.9 | G2: 10.7 | H2: 1.4 | I2: 0.8 | J2: 1.7 | K2: 3.7
A3: 2 | B3: Karl-Anthony Towns | D3: C | E3: 20.1 | F3: 11.9 | G3: 3 | H3: 0.9 | I3: 0.5 | J3: 1.5 | K3: 2.5
A4: 3 | B4: Donovan Clingan | D4: C | E4: 12.1 | F4: 11.6 | G4: 2.1 | H4: 0.6 | I4: 1.7 | J4: 1.1 | K4: 1.2
A5: 4 | B5: Victor Wembanyama | D5: C | E5: 25 | F5: 11.5 | G5: 3.1 | H5: 1 | I5: 3.1 | J5: 1.9 | K5: 2.4
A6: 5 | B6: Rudy Gobert | D6: C | E6: 10.9 | F6: 11.5 | G6: 1.7 | H6: 0.8 | I6: 1.6 | J6: 0 | K6: 1.4
A7: 6 | B7: Domantas Sabonis | D7: PF/C | E7: 15.8 | F7: 11.4 | G7: 4.1 | H7: 0.9 | I7: 0.2 | J7: 0.3 | K7: 2.7
A8: 7 | B8: Anthony Davis | D8: C | E8: 20.4 | F8: 11.1 | G8: 2.8 | H8: 1.1 | I8: 1.7 | J8: 0.5 | K8: 2.1
A9: 8 | B9: Zach Edey | D9: C | E9: 13.6 | F9: 11.1 | G9: 1.1 | H9: 0.6 | I9: 1.9 | J9: 0.1 | K9: 2.4
A10: 9 | B10: Walker Kessler | D10: C | E10: 14.4 | F10: 10.8 | G10: 3 | H10: 1.4 | I10: 1.8 | J10: 1.2 | K10: 3.2
A11: 10 | B11: Ivica Zubac | D11: C | E11: 14.1 | F11: 10.6 | G11: 2.2 | H11: 0.4 | I11: 0.8 | J11: 0 | K11: 1.8
A12: 11 | B12: Jalen Duren | D12: C | E12: 19.5 | F12: 10.5 | G12: 2 | H12: 0.8 | I12: 0.8 | J12: 0 | K12: 1.9
A13: 12 | B13: Julian Reese | D13: PF | E13: 11.8 | F13: 10.5 | G13: 1.8 | H13: 1.4 | I13: 0.6 | J13: 0 | K13: 2.5
... A447: 446 | B447: Fred Vanvleet | D447: PG/SG | E447: 0 | F447: 0 | G447: 0 | H447: 0 | I447: 0 | J447: 0 | K447: 0

Sheet teams
A1: team_id | B1: team_name | C1: manager_name | D1: pts_avg | E1: trb_avg | F1: ast_avg | G1: stl_avg | H1: blk_avg | I1: three_p_avg | J1: tov_avg | K1: matchup_win_avg
A2: 1 | B2: Alabama Black Bears
A3: 2 | B3: Franca Celtics
A4: 3 | B4: Guarulhos Nuggets
A5: 4 | B5: Itajubá Rabbits
A6: 5 | B6: Kaipiras da Gema
A7: 6 | B7: Miami Barons
A8: 7 | B8: Montreal Turtles
A9: 8 | B9: New Orleans Dancers
A10: 9 | B10: Osasco Heat
A11: 10 | B11: Pelotas Vikings
A12: 11 | B12: Pernambuco Pharynx
A13: 12 | B13: Recife Black Diamond
... A15: 14 | B15: Tchêltics da Peleia

Sheet lineup_active
A1: team_id | B1: player_id | C1: slot | D1: is_active | E1: scenario_id
A2: 7 | B2: 7 | C2: PF | D2: 1 | F2: =VLOOKUP(B2,players!A:B,2) -> Anthony Davis
A3: 7 | B3: 20 | C3: C | D3: 1 | F3: =VLOOKUP(B3,players!A:B,2) -> Kel'el Ware
A4: 7 | B4: 88 | C4: SF | D4: 1 | F4: =VLOOKUP(B4,players!A:B,2) -> Ausar Thompson
A5: 7 | B5: 247 | C5: PG | D5: 1 | F5: =VLOOKUP(B5,players!A:B,2) -> Ja Morant
A6: 7 | B6: 40 | C6: UTIL | D6: 1 | F6: =VLOOKUP(B6,players!A:B,2) -> Scottie Barnes
A7: 7 | B7: 102 | C7: SG | D7: 1 | F7: =VLOOKUP(B7,players!A:B,2) -> Dejounte Murray
A8: 1 | B8: 39 | C8: C | D8: 1 | F8: =VLOOKUP(B8,players!A:B,2) -> Onyeka Okongwu
A9: 1 | B9: 78 | C9: PF | D9: 1 | F9: =VLOOKUP(B9,players!A:B,2) -> Matas Buzelis
A10: 1 | B10: 128 | C10: SG | D10: 1 | F10: =VLOOKUP(B10,players!A:B,2) -> Anthony Edwards
A11: 1 | B11: 176 | C11: PG | D11: 1 | F11: =VLOOKUP(B11,players!A:B,2) -> Tyrese Maxey
A12: 1 | B12: 181 | C12: UTIL | D12: 1 | F12: =VLOOKUP(B12,players!A:B,2) -> Donte DiVincenzo
A13: 1 | B13: 205 | C13: SF | D13: 1 | F13: =VLOOKUP(B13,players!A:B,2) -> Mikal Bridges
... A85: 14 | B85: 145 | C85: PG | D85: 1 | F85: =VLOOKUP(B85,players!A:B,2) -> LaMelo Ball

Sheet fines
A1: team_id | B1: fine_26_27 | C1: fine_27_28 | D1: fine_28_29 | E1: fine_29_30 | F1: notes
A2: 1 | B2: 3653000 | C2: 465000 | D2: 465000
A3: 2
A4: 3 | B4: 4000000 | C4: 1200000
A5: 4
A6: 5 | B6: 1200000 | C6: 450000
A7: 6 | B7: 1200000 | C7: 1200000
A8: 7 | B8: 3750000
A9: 8
A10: 9
A11: 10
A12: 11
A13: 12 | B13: 1200000 | C13: 1200000
A14: 13 | B14: 150000
A15: 14 | B15: 600000 | C15: 600000

Sheet transactions_leg
A1: transactionid | B1: transactiontype | C1: transaction_date | D1: season | E1: from_team_id | F1: to_team_id | G1: initiated_by | H1: status | I1: notes
B2: Trade | G2: username
B3: Pick Swap
B4: DEV_PROMOTION
B5: DEV_DEMOTION
B6: CUT
B7: SIGN
A10: transaction_id | B10: item_id | C10: item_type | D10: asset_id | E10: from_team_id | F10: to_team_id | G10: from_roster_type | H10: to_roster_type | I10: effective_season | J10: item_notes
C11: PLAYER | D11: 247 | G11: MAIN | H11: MAIN
C12: PICK | D12: P2026R1T07 | G12: DEV | H12: DEV
G13: null | H13: null

Sheet games
A1: id_jogo | B1: id_time_1 | C1: nome_time_1 | D1: pontos_time_1 | E1: pontos_time_2 | F1: id_time_2 | G1: nome_time_2 | H1: rodada
A2: 1 | B2: 14 | C2: Tchêltics da Peleia | D2: 3 | E2: 4 | F2: 5 | G2: Kaipiras da Gema | H2: 1
A3: 2 | B3: 6 | C3: Miami Barons | F3: 1 | G3: Alabama Black Bears | H3: 1
A4: 3 | B4: 8 | C4: New Orleans Dancers | F4: 4 | G4: Itajubá Rabbits | H4: 1
A5: 4 | B5: 9 | C5: Osasco Heat | F5: 2 | G5: Franca Celtics | H5: 1
A6: 5 | B6: 3 | C6: Guarulhos Nuggets | F6: 12 | G6: Recife Black Diamond | H6: 1
A7: 6 | B7: 13 | C7: RJ Black Mamba | F7: 11 | G7: Pernambuco Pharynx | H7: 1
A8: 7 | B8: 7 | C8: Montreal Turtles | F8: 10 | G8: Pelotas Vikings | H8: 1
A9: 8 | B9: 14 | C9: Tchêltics da Peleia | F9: 6 | G9: Miami Barons | H9: 2
A10: 9 | B10: 5 | C10: Kaipiras da Gema | F10: 10 | G10: Pelotas Vikings | H10: 2
A11: 10 | B11: 8 | C11: New Orleans Dancers | F11: 1 | G11: Alabama Black Bears | H11: 2
A12: 11 | B12: 9 | C12: Osasco Heat | F12: 4 | G12: Itajubá Rabbits | H12: 2
A13: 12 | B13: 3 | C13: Guarulhos Nuggets | F13: 2 | G13: Franca Celtics | H13: 2
A14: 13 | B14: 13 | C14: RJ Black Mamba | F14: 12 | G14: Recife Black Diamond | H14: 2
... A274: 273 | B274: 6 | C274: Miami Barons | F274: 4 | G274: Itajubá Rabbits | H274: 39

Sheet Semana
A1: SEMANANUM | B1: SEMANAINICIO | C1: TEAMABBR | D1: TEAMNAME | E1: JOGONASEMANA | F1: GAMEDATE | G1: GAMEID | H1: OPPONENTABBR | I1: OPPONENTNAME | J1: HOMEAWAY
A2: 1 | B2: 46314 | C2: ATL | D2: Atlanta Hawks | E2: 1 | F2: 46316 | G2: 0022600085 | H2: ORL | I2: Orlando Magic | J2: A
A3: 1 | B3: 46314 | C3: ATL | D3: Atlanta Hawks | E3: 2 | F3: 46318 | G3: 0022600094 | H3: CHA | I3: Charlotte Hornets | J3: A
A4: 1 | B4: 46314 | C4: ATL | D4: Atlanta Hawks | E4: 3 | F4: 46319 | G4: 0022600107 | H4: HOU | I4: Houston Rockets | J4: H
A5: 1 | B5: 46314 | C5: BKN | D5: Brooklyn Nets | E5: 1 | F5: 46316 | G5: 0022600087 | H5: CHA | I5: Charlotte Hornets | J5: H
A6: 1 | B6: 46314 | C6: BKN | D6: Brooklyn Nets | E6: 2 | F6: 46319 | G6: 0022600105 | H6: CLE | I6: Cleveland Cavaliers | J6: A
A7: 1 | B7: 46314 | C7: BKN | D7: Brooklyn Nets | E7: 3 | F7: 46320 | G7: 0022600113 | H7: IND | I7: Indiana Pacers | J7: H
A8: 1 | B8: 46314 | C8: BOS | D8: Boston Celtics | E8: 1 | F8: 46315 | G8: 0022600001 | H8: DET | I8: Detroit Pistons | J8: A
A9: 1 | B9: 46314 | C9: BOS | D9: Boston Celtics | E9: 2 | F9: 46318 | G9: 0022600008 | H9: NYK | I9: New York Knicks | J9: H
A10: 1 | B10: 46314 | C10: CHA | D10: Charlotte Hornets | E10: 1 | F10: 46316 | G10: 0022600087 | H10: BKN | I10: Brooklyn Nets | J10: A
A11: 1 | B11: 46314 | C11: CHA | D11: Charlotte Hornets | E11: 2 | F11: 46318 | G11: 0022600094 | H11: ATL | I11: Atlanta Hawks | J11: H
A12: 1 | B12: 46314 | C12: CHA | D12: Charlotte Hornets | E12: 3 | F12: 46319 | G12: 0022600104 | H12: MIA | I12: Miami Heat | J12: H
A13: 1 | B13: 46314 | C13: CHI | D13: Chicago Bulls | E13: 1 | F13: 46316 | G13: 0022600088 | H13: TOR | I13: Toronto Raptors | J13: A
... A2073: 25 | B2073: 46482 | C2073: WAS | D2073: Washington Wizards | E2073: 3 | F2073: 46486 | G2073: 0022601177 | H2073: MIA | I2073: Miami Heat | J2073: A

Sheet transactions
A1: transactionid | B1: transactiontype | C1: transactiondate | D1: season | E1: fromteamid | F1: toteamid | G1: initiatedby | H1: status | I1: notes | J1: transaction_id
A2: 13 | B2: Pick Swap | C2: 2026-07-15 | D2: 2026-27 | E2: 5 | F2: 7 | G2: Gema | H2: Approved | J2: 13
A3: 14 | B3: Pick Swap | C3: 2026-07-15 | D3: 2026-27 | E3: 7 | F3: 5 | G3: Gema | H3: Approved | J3: 14
A4: 15 | B4: Trade | C4: 2026-07-15 | D4: 2026-27 | E4: 5 | F4: 10 | G4: Gema | H4: Approved | J4: 15
A5: 16 | B5: Trade | C5: 2026-07-15 | D5: 2026-27 | E5: 10 | F5: 5 | G5: Gema | H5: Approved | J5: 16
A6: 17 | B6: Trade | C6: 2026-07-15 | D6: 2026-27 | E6: 5 | F6: 14 | G6: Gema | H6: Approved | J6: 17
A7: 18 | B7: Trade | C7: 2026-07-15 | D7: 2026-27 | E7: 14 | F7: 5 | G7: Gema | H7: Approved | J7: 18
A8: 19 | B8: Trade | C8: 2026-07-15 | D8: 2026-27 | E8: 12 | F8: 7 | G8: Diamond | H8: Approved | J8: 19
A9: 20 | B9: Trade | C9: 2026-07-15 | D9: 2026-27 | E9: 7 | F9: 12 | G9: Diamond | H9: Approved | J9: 20
A10: 21 | B10: Trade | C10: 2026-07-15 | D10: 2026-27 | E10: 5 | F10: 14 | G10: Gema | H10: Approved | J10: 21
A11: 22 | B11: Trade | C11: 2026-07-15 | D11: 2026-27 | E11: 14 | F11: 5 | G11: Gema | H11: Approved | J11: 22
A12: 23 | B12: Trade | C12: 2026-07-15 | D12: 2026-27 | E12: 14 | F12: 13 | G12: Peleia | H12: Approved | J12: 23
A13: 24 | B13: Trade | C13: 2026-07-15 | D13: 2026-27 | E13: 13 | F13: 14 | G13: Peleia | H13: Approved | J13: 24
... A29: 40 | B29: DEV_DEMOTION | C29: 2026-07-15 | D29: 2026-27 | E29: 2 | F29: 2 | G29: Celtics | H29: Approved | J29: 40
A30: 41 | B30: CUT | C30: 2026-07-15 | D30: 2026-27 | E30: 5 | F30: null | G30: Gema | H30: Approved | J30: 41
A31: 42 | B31: CUT | C31: 2026-07-15 | D31: 2026-27 | E31: 13 | F31: null | G31: BlackMamba | H31: Approved | J31: 42
A32: 1 | B32: TRADE | C32: 2026-07-15 | D32: 26_27 | E32: 6 | F32: 1 | G32: admin@auction.local | H32: DONE | J32: 1
A33: 2 | B33: TRADE | C33: 2026-07-15 | D33: 26_27 | E33: 6 | F33: 1 | G33: admin@auction.local | H33: DONE | J33: 2
A34: 3 | B34: DEV_DEMOTION | C34: 2026-07-15 | D34: 26_27 | E34: 7 | F34: 7 | G34: admin@auction.local | H34: DONE | J34: 3
A35: 4 | B35: TRADE | C35: 2026-07-16 | D35: 26_27 | E35: 7 | F35: 5 | G35: admin@auction.local | H35: DONE | J35: 4
A36: 5 | B36: DEV_DEMOTION | C36: 2026-07-15 | D36: 26_27 | E36: 7 | F36: 7 | G36: admin@auction.local | H36: DONE | J36: 5
A37: 6 | B37: DEV_PROMOTION | C37: 2026-07-15 | D37: 26_27 | E37: 2 | F37: 2 | G37: admin@auction.local | H37: DONE | J37: 6
A38: 7 | B38: ROSTER_MOVE | C38: 2026-07-16 | D38: 26_27 | E38: 7 | F38: 7 | G38: admin@auction.local | H38: DONE | J38: 7
A39: 8 | B39: ROSTER_MOVE | C39: 2026-07-16 | D39: 26_27 | E39: 7 | F39: 7 | G39: admin@auction.local | H39: DONE | J39: 8
A40: 9 | B40: TRADE | C40: 2026-07-17 | D40: 26_27 | E40: 2 | F40: 13 | G40: admin@auction.local | H40: DONE | J40: 9
A41: 10 | B41: WAIVE | C41: 2026-07-18 | D41: 26_27 | E41: 6 | G41: admin@auction.local | H41: DONE | J41: 10
A42: 11 | B42: WAIVE | C42: 2026-07-18 | D42: 26_27 | E42: 7 | G42: admin@auction.local | H42: DONE | J42: 11
A43: 12 | B43: MOVE | C43: 2026-07-22 | D43: 26_27 | E43: 6 | F43: 6 | G43: admin@auction.local | H43: DONE | J43: 12
A44: 14 | B44: MOVE | C44: 2026-07-29 | D44: 26_27 | E44: 13 | F44: 13 | G44: admin@auction.local | H44: APPROVED | J44: 15
B45: MOVE | C45: 2026-07-29 | D45: 26_27 | E45: 13 | F45: 13 | G45: admin@auction.local | H45: DONE | J45: 43
B46: MOVE | C46: 2026-07-29 | D46: 26_27 | E46: 13 | F46: 13 | G46: admin@auction.local | H46: DONE | J46: 44
B47: MOVE | C47: 2026-07-29 | D47: 26_27 | E47: 13 | F47: 13 | G47: admin@auction.local | H47: DONE | J47: 45
B48: MOVE | C48: 2026-08-02 | D48: 26_27 | E48: 7 | F48: 7 | G48: admin@auction.local | H48: DONE | J48: 46
B49: MOVE | C49: 2026-08-02 | D49: 26_27 | E49: 7 | F49: 7 | G49: admin@auction.local | H49: DONE | J49: 47
B50: WAIVE | C50: 2026-08-05 | D50: 26_27 | E50: 3 | G50: admin@auction.local | H50: DONE | J50: 48
B51: MOVE | C51: 2026-08-05 | D51: 26_27 | E51: 3 | F51: 3 | G51: admin@auction.local | H51: DONE | J51: 49
B52: WAIVE | C52: 2026-08-09 | D52: 26_27 | E52: 1 | G52: admin@auction.local | H52: DONE | J52: 50
B53: TRADE | C53: 2026-08-20 | D53: 26_27 | E53: 5 | F53: 2 | G53: admin@auction.local | H53: DONE | J53: 51
B54: MOVE | C54: 2026-08-20 | D54: 26_27 | E54: 2 | F54: 2 | G54: admin@auction.local | H54: DONE | J54: 52
B55: TRADE | C55: 2026-08-20 | D55: 26_27 | E55: 2 | F55: 5 | G55: admin@auction.local | H55: DONE | J55: 53
...

Sheet transactionitems
A1: transaction_id | B1: item_id | C1: item_type | D1: asset_id | E1: from_team_id | F1: to_team_id | G1: from_roster_type | H1: to_roster_type | I1: effective_season | J1: item_notes | L1: __dup1 | M1: __dup2 | N1: __dup3
A2: 13 | B2: P2026_R1_T07 | C2: pick | D2: P2026_R1_T07 | E2: 5 | F2: 7 | G2: null | H2: null | I2: 2026-27
A3: 13 | B3: P2026_R1_T04 | C3: pick | D3: P2026_R1_T04 | E3: 7 | F3: 5 | G3: null | H3: null | I3: 2026-27
A4: 14 | B4: P2026_R1_T10 | C4: pick | D4: P2026_R1_T10 | E4: 7 | F4: 5 | G4: null | H4: null | I4: 2026-27
A5: 16 | B5: P2026_R2_T10 | C5: pick | D5: P2026_R2_T10 | E5: 10 | F5: 5 | G5: null | H5: null | I5: 2026-27
A6: 15 | B6: 9 | C6: player | D6: 9 | E6: 5 | F6: 10 | G6: main | H6: main | I6: 2026-27
A7: 18 | B7: 219 | C7: player | D7: 219 | E7: 14 | F7: 5 | G7: main | H7: main | I7: 2026-27
A8: 17 | B8: 220 | C8: player | D8: 220 | E8: 5 | F8: 14 | G8: main | H8: main | I8: 2026-27
A9: 20 | B9: 194 | C9: player | D9: 194 | E9: 7 | F9: 12 | G9: main | H9: main | I9: 2026-27
A10: 19 | B10: 158 | C10: player | D10: 158 | E10: 12 | F10: 7 | G10: main | H10: main | I10: 2026-27
A11: 19 | B11: 247 | C11: player | D11: 247 | E11: 12 | F11: 7 | G11: main | H11: main | I11: 2026-27
A12: 19 | B12: 88 | C12: player | D12: 88 | E12: 12 | F12: 7 | G12: main | H12: main | I12: 2026-27
A13: 21 | B13: 2 | C13: player | D13: 2 | E13: 5 | F13: 14 | G13: main | H13: main | I13: 2026-27
A14: 22 | B14: 152 | C14: player | D14: 152 | E14: 14 | F14: 5 | G14: main | H14: main | I14: 2026-27
A15: 21 | B15: P2026_R1_T14 | C15: pick | D15: P2026_R1_T14 | E15: 5 | F15: 14 | G15: null | H15: null | I15: 2026-27
A16: 22 | B16: P2026_R1_T5 | C16: pick | D16: P2026_R1_T5 | E16: 14 | F16: 5 | G16: null | H16: null | I16: 2026-27
A17: 23 | B17: P2026_R1_T13 | C17: pick | D17: P2026_R1_T13 | E17: 14 | F17: 13 | G17: null | H17: null | I17: 2026-27
A18: 23 | B18: P2026_R2_T14 | C18: pick | D18: P2026_R2_T14 | E18: 14 | F18: 13 | G18: null | H18: null | I18: 2026-27
A19: 24 | B19: 73 | C19: player | D19: 73 | E19: 13 | F19: 14 | G19: main | H19: main | I19: 2026-27
A20: 23 | B20: 241 | C20: player | D20: 241 | E20: 14 | F20: 13 | G20: main | H20: main | I20: 2026-27
A21: 23 | B21: 121 | C21: player | D21: 121 | E21: 14 | F21: 13 | G21: main | H21: main | I21: 2026-27
A22: 25 | B22: 177 | C22: player | D22: 177 | E22: 14 | F22: 11 | G22: main | H22: main | I22: 2026-27
A23: 26 | B23: 66 | C23: player | D23: 66 | E23: 11 | F23: 14 | G23: main | H23: main | I23: 2026-27
A24: 28 | B24: 145 | C24: player | D24: 145 | E24: 6 | F24: 14 | G24: main | H24: main | I24: 2026-27
A25: 27 | B25: 56 | C25: player | D25: 56 | E25: 14 | F25: 6 | G25: main | H25: main | I25: 2026-27
A26: 27 | B26: 93 | C26: player | D26: 93 | E26: 14 | F26: 6 | G26: main | H26: main | I26: 2026-27
A27: 27 | B27: 161 | C27: player | D27: 161 | E27: 14 | F27: 6 | G27: main | H27: main | I27: 2026-27
A28: 27 | B28: P2026_R1_T5 | C28: pick | D28: P2026_R1_T5 | E28: 14 | F28: 6 | G28: null | H28: null | I28: 2026-27
A29: 29 | B29: P2026_R1_T13 | C29: pick | D29: P2026_R1_T13 | E29: 13 | F29: 5 | G29: null | H29: null | I29: 2026-27
A30: 29 | B30: P2026_R2_T14 | C30: pick | D30: P2026_R2_T14 | E30: 13 | F30: 5 | G30: null | H30: null | I30: 2026-27
A31: 30 | B31: P2026_R1_T04 | C31: pick | D31: P2026_R1_T04 | E31: 5 | F31: 13 | G31: null | H31: null | I31: 2026-27
A32: 29 | B32: 409 | C32: player | D32: 409 | E32: 13 | F32: 5 | G32: main | H32: main | I32: 2026-27
A33: 29 | B33: 48 | C33: player | D33: 48 | E33: 13 | F33: 5 | G33: main | H33: main | I33: 2026-27
A34: 30 | B34: 414 | C34: player | D34: 414 | E34: 5 | F34: 13 | G34: main | H34: main | I34: 2026-27
A35: 32 | B35: 238 | C35: player | D35: 238 | E35: 5 | F35: 14 | G35: main | H35: main | I35: 2026-27
A36: 31 | B36: 133 | C36: player | D36: 133 | E36: 14 | F36: 5 | G36: main | H36: main | I36: 2026-27
A37: 33 | B37: 143 | C37: player | D37: 143 | E37: 2 | F37: 5 | G37: main | H37: main | I37: 2026-27
A38: 33 | B38: 72 | C38: player | D38: 72 | E38: 2 | F38: 5 | G38: main | H38: main | I38: 2026-27
A39: 34 | B39: 219 | C39: player | D39: 219 | E39: 5 | F39: 2 | G39: main | H39: main | I39: 2026-27
A40: 34 | B40: 49 | C40: player | D40: 49 | E40: 5 | F40: 2 | G40: main | H40: main | I40: 2026-27
...

Sheet roster
A1: team_id | B1: player_id | C1: roster_order | D1: salarie_26_27 | E1: option_26_27 | F1: salarie_27_28 | G1: option_27_28 | H1: salarie_28_29 | I1: option_28_29 | J1: salarie_29_30 | K1: option_29_30 | L1: Jogador
A2: 5 | B2: 204 | C2: 1 | D2: 1000000 | F2: 1000000 | L2: =VLOOKUP(B2,players!A:B,2) -> Anthony Black
A3: 7 | B3: 147 | C3: 3 | D3: 1000000 | F3: 1000000 | L3: =VLOOKUP(B3,players!A:B,2) -> Christian Braun
A4: 7 | B4: 50 | C4: 5 | D4: 3000000 | L4: =VLOOKUP(B4,players!A:B,2) -> P.J. Washington
A5: 7 | B5: 178 | C5: 7 | D5: 1000000 | L5: =VLOOKUP(B5,players!A:B,2) -> De'Andre Hunter
A6: 7 | B6: 7 | C6: 8 | D6: 9000000 | F6: 9000000 | L6: =VLOOKUP(B6,players!A:B,2) -> Anthony Davis
A7: 7 | B7: 20 | C7: 9 | D7: 1000000 | F7: 1000000 | G7: Sim | L7: =VLOOKUP(B7,players!A:B,2) -> Kel'el Ware
A8: 7 | B8: 88 | C8: 10 | D8: 6500000 | L8: =VLOOKUP(B8,players!A:B,2) -> Ausar Thompson
A9: 7 | B9: 247 | C9: 11 | D9: 13000000 | F9: 13000000 | H9: 13000000 | L9: =VLOOKUP(B9,players!A:B,2) -> Ja Morant
A10: 7 | B10: 40 | C10: 12 | D10: 29500000 | F10: 29500000 | H10: 29500000 | L10: =VLOOKUP(B10,players!A:B,2) -> Scottie Barnes
A11: 7 | B11: 102 | C11: 13 | D11: 23000000 | L11: =VLOOKUP(B11,players!A:B,2) -> Dejounte Murray
A12: 1 | B12: 172 | C12: 3 | D12: 7500000 | F12: 8500000 | G12: Sim | H12: 9000000 | I12: Sim | L12: =VLOOKUP(B12,players!A:B,2) -> Ace Bailey
A13: 3 | B13: 146 | C13: 4 | D13: 1000000 | F13: 1000000 | L13: =VLOOKUP(B13,players!A:B,2) -> Andrew Wiggins
A14: 1 | B14: 355 | C14: 6 | D14: 1000000 | F14: 1000000 | G14: Sim | H14: 1000000 | I14: Sim | L14: =VLOOKUP(B14,players!A:B,2) -> Asa Newell
A15: 1 | B15: 39 | C15: 7 | D15: 6500000 | F15: 6500000 | L15: =VLOOKUP(B15,players!A:B,2) -> Onyeka Okongwu
A16: 1 | B16: 78 | C16: 8 | D16: 4200000 | F16: 4500000 | G16: Sim | L16: =VLOOKUP(B16,players!A:B,2) -> Matas Buzelis
A17: 1 | B17: 128 | C17: 9 | D17: 40000000 | F17: 40000000 | H17: 40000000 | L17: =VLOOKUP(B17,players!A:B,2) -> Anthony Edwards
A18: 1 | B18: 176 | C18: 10 | D18: 30500000 | F18: 30500000 | H18: 30500000 | L18: =VLOOKUP(B18,players!A:B,2) -> Tyrese Maxey
A19: 5 | B19: 187 | C19: 13 | D19: 1000000 | F19: 1000000 | L19: =VLOOKUP(B19,players!A:B,2) -> Jay Huff
A20: 1 | B20: 439 | C20: 15 | D20: 1000000 | F20: 1000000 | H20: 1000000 | I20: Sim | J20: 1000000 | K20: Sim | L20: =VLOOKUP(B20,players!A:B,2) -> Karim López
A21: 2 | B21: 320 | C21: 1 | D21: 1000000 | F21: 1000000 | G21: Sim | L21: =VLOOKUP(B21,players!A:B,2) -> Cam Spencer
A22: 2 | B22: 21 | C22: 2 | D22: 23500000 | F22: 23500000 | H22: 23500000 | L22: =VLOOKUP(B22,players!A:B,2) -> Alperen Şengün
A23: 2 | B23: 96 | C23: 3 | D23: 15000000 | L23: =VLOOKUP(B23,players!A:B,2) -> Kevin Durant
A24: 2 | B24: 219 | C24: 5 | D24: 7000000 | F24: 7000000 | H24: 7000000 | L24: =VLOOKUP(B24,players!A:B,2) -> Jalen Green
A25: 2 | B25: 144 | C25: 6 | D25: 6000000 | F25: 6000000 | L25: =VLOOKUP(B25,players!A:B,2) -> Tyler Herro
A26: 2 | B26: 362 | C26: 7 | D26: 21500000 | F26: 21500000 | H26: 21500000 | L26: =VLOOKUP(B26,players!A:B,2) -> Trae Young
A27: 2 | B27: 69 | C27: 10 | D27: 3100000 | F27: 3100000 | H27: 3100000 | L27: =VLOOKUP(B27,players!A:B,2) -> Bobby Portis
A28: 2 | B28: 49 | C28: 11 | D28: 3200000 | F28: 3400000 | G28: Sim | H28: 3700000 | I28: Sim | L28: =VLOOKUP(B28,players!A:B,2) -> Derik Queen
A29: 8 | B29: 237 | C29: 2 | D29: 4000000 | F29: 4000000 | L29: =VLOOKUP(B29,players!A:B,2) -> Nickeil Alexander-Walker
A30: 6 | B30: 119 | C30: 3 | D30: 5000000 | F30: 5000000 | H30: 5000000 | J30: 5000000 | L30: =VLOOKUP(B30,players!A:B,2) -> Kyshawn George
A31: 3 | B31: 206 | C31: 4 | D31: 5000000 | L31: =VLOOKUP(B31,players!A:B,2) -> Cameron Johnson
A32: 13 | B32: 112 | C32: 5 | D32: 5500000 | L32: =VLOOKUP(B32,players!A:B,2) -> Myles Turner
A33: 14 | B33: 23 | C33: 6 | D33: 1500000 | F33: 1500000 | H33: 1500000 | L33: =VLOOKUP(B33,players!A:B,2) -> Mitchell Robinson
A34: 3 | B34: 11 | C34: 7 | D34: 14000000 | F34: 14000000 | H34: 14000000 | L34: =VLOOKUP(B34,players!A:B,2) -> Jalen Duren
A35: 3 | B35: 36 | C35: 8 | D35: 40000000 | F35: 40000000 | H35: 40000000 | L35: =VLOOKUP(B35,players!A:B,2) -> Luka Dončić
A36: 3 | B36: 68 | C36: 9 | D36: 6000000 | L36: =VLOOKUP(B36,players!A:B,2) -> Kawhi Leonard
A37: 3 | B37: 85 | C37: 10 | D37: 14000000 | F37: 14000000 | L37: =VLOOKUP(B37,players!A:B,2) -> Jaren Jackson Jr.
A38: 3 | B38: 117 | C38: 11 | D38: 6500000 | F38: 6500000 | H38: 6500000 | L38: =VLOOKUP(B38,players!A:B,2) -> OG Anunoby
A39: 3 | B39: 142 | C39: 12 | D39: 5000000 | L39: =VLOOKUP(B39,players!A:B,2) -> Kyrie Irving
A40: 4 | B40: 379 | C40: 1 | D40: 1000000 | F40: 1000000 | G40: Sim | H40: 1000000 | I40: Sim | L40: =VLOOKUP(B40,players!A:B,2) -> Nolan Traoré
...

Sheet development
A1: team_id | B1: player_id | C1: roster_order | D1: salarie_26_27 | E1: option_26_27 | F1: salarie_27_28 | G1: option_27_28 | H1: salarie_28_29 | I1: option_28_29 | J1: salarie_29_30 | K1: option_29_30 | L1: Jogador
A2: 7 | B2: 370 | C2: 1 | D2: 3600000 | F2: 3900000 | G2: Sim | L2: =VLOOKUP(B2,players!A:B,2) -> Rob Dillingham
A3: 7 | B3: 214 | C3: 2 | D3: 1000000 | F3: 1000000 | G3: Sim | L3: =VLOOKUP(B3,players!A:B,2) -> Tristan Da Silva
A4: 1 | B4: 319 | C4: 1 | D4: 1000000 | F4: 1000000 | G4: Sim | L4: =VLOOKUP(B4,players!A:B,2) -> Isaiah Collier
A5: 1 | B5: 99 | C5: 2 | D5: 1000000 | F5: 1000000 | G5: Sim | H5: 1000000 | I5: Sim | L5: =VLOOKUP(B5,players!A:B,2) -> Ryan Kalkbrenner
A6: 2 | B6: 365 | C6: 2 | D6: 1000000 | F6: 1000000 | G6: Sim | H6: 1000000 | I6: Sim | L6: =VLOOKUP(B7,players!A:B,2) -> Johnny Furphy
A7: 2 | B7: 407 | C7: 3 | D7: 1000000 | F7: 1000000 | G7: Sim | L7: =VLOOKUP(B8,players!A:B,2) -> Will Riley
A8: 2 | B8: 290 | C8: 12 | D8: 1000000 | F8: 1000000 | G8: Sim | H8: 1000000 | L8: =VLOOKUP(B10,players!A:B,2) -> Nikola Topić
A9: 2 | B9: 423 | C9: 9 | D9: 4000000 | F9: 4500000 | H9: 5000000 | I9: Sim | J9: 5500000 | K9: Sim | L9: =VLOOKUP(B11,players!A:B,2) -> Jase Richardson
A10: 3 | B10: 377 | C10: 1 | D10: 1000000 | F10: 1000000 | G10: Sim | H10: 1000000 | I10: Sim | L10: =VLOOKUP(B12,players!A:B,2) -> Tidjane Salaün
A11: 3 | B11: 408 | C11: 2 | D11: 3400000 | F11: 3700000 | G11: Sim | L11: =VLOOKUP(B13,players!A:B,2) -> Kyle Filipowski
A12: 6 | B12: 192 | C12: 1 | D12: 3200000 | F12: 3500000 | G12: Sim | L12: =VLOOKUP(B17,players!A:B,2) -> Tre Johnson
A13: 8 | B13: 47 | C13: 1 | D13: 1000000 | F13: 1000000 | G13: Sim | L13: =VLOOKUP(B18,players!A:B,2) -> Ja'Kobe Walter
A14: 9 | B14: 108 | C14: 1 | D14: 5000000 | F14: 5500000 | G14: Sim | H14: 6000000 | I14: Sim | L14: =VLOOKUP(B19,players!A:B,2) -> Thomas Sorber
A15: 9 | B15: 123 | C15: 2 | D15: 1000000 | F15: 1000000 | G15: Sim | L15: =VLOOKUP(B20,players!A:B,2) -> Carter Bryant
A16: 9 | B16: 410 | C16: 3 | D16: 1000000 | F16: 1000000 | G16: Sim | L16: =VLOOKUP(B21,players!A:B,2) -> Devin Carter
A17: 10 | B17: 297 | C17: 1 | D17: 5500000 | F17: 6000000 | G17: Sim | H17: 6500000 | I17: Sim | L17: =VLOOKUP(B22,players!A:B,2) -> Kaman Maluach
A18: 10 | B18: 313 | C18: 2 | D18: 1000000 | F18: 1000000 | L18: =VLOOKUP(B23,players!A:B,2) -> Jaylen Wells
A19: 10 | B19: 411 | C19: 4 | D19: 1000000 | F19: 1000000 | G19: Sim | H19: 1000000 | I19: Sim | L19: =VLOOKUP(B24,players!A:B,2) -> Noah Essengue
A20: 11 | B20: 412 | C20: 1 | D20: 3200000 | F20: 3500000 | G20: Sim | L20: =VLOOKUP(B25,players!A:B,2) -> Darius Acuff
A21: 13 | B21: 252 | C21: 1 | D21: 1000000 | F21: 1000000 | G21: Sim | L21: =VLOOKUP(B26,players!A:B,2) -> Labaron Philon Jr.
A22: 13 | B22: 414 | C22: 2 | D22: 3600000 | F22: 3800000 | G22: Sim | H22: 4100000 | I22: Sim | L22: =VLOOKUP(B27,players!A:B,2) -> Cameron Boozer
A23: 14 | B23: 259 | C23: 1 | D23: 1000000 | L23: =VLOOKUP(B28,players!A:B,2) -> Christian Anderson Jr.
A24: 14 | B24: 415 | C24: 2 | D24: 3800000 | F24: 4000000 | G24: Sim | H24: 4200000 | I24: Sim | L24: =VLOOKUP(B29,players!A:B,2) -> Morez Johnson Jr.
A25: 7 | B25: 421 | C25: 3 | D25: 5000000 | F25: 5500000 | H25: 6000000 | I25: Sim | J25: 6500000 | K25: Sim | L25: =VLOOKUP(B30,players!A:B,2) -> Sergio de Larrea
A26: 7 | B26: 435 | C26: 4 | D26: 1000000 | F26: 1000000 | H26: 1000000 | I26: Sim | J26: 1000000 | K26: Sim | L26: =VLOOKUP(B31,players!A:B,2) -> Cameron Carr
A27: 6 | B27: 419 | C27: 14 | D27: 7000000 | F27: 7500000 | H27: 8250000 | I27: Sim | J27: 9000000 | K27: Sim | L27: =VLOOKUP(B32,players!A:B,2) -> Bruce Thornton
A28: 6 | B28: 444 | C28: 16 | D28: 1000000 | F28: 1000000 | H28: 1000000 | I28: Sim | J28: 1000000 | K28: Sim | L28: =VLOOKUP(B33,players!A:B,2) -> Brayden Burries
A29: 13 | B29: 426 | C29: 14 | D29: 3400000 | F29: 3600000 | H29: 3800000 | I29: Sim | J29: 4100000 | K29: Sim | L29: =VLOOKUP(B34,players!A:B,2) -> Collin Murray-Boyles
A30: 13 | B30: 440 | C30: 14 | D30: 1000000 | F30: 1000000 | H30: 1000000 | I30: Sim | J30: 1000000 | K30: Sim | L30: =VLOOKUP(B35,players!A:B,2) -> Maxime Raynaud
A31: 13 | B31: 430 | C31: 13 | D31: 2600000 | F31: 2800000 | H31: 3000000 | I31: Sim | J31: 3300000 | K31: Sim | L31: =VLOOKUP(B36,players!A:B,2) -> Egor Dёmin
A32: 7 | B32: 437 | C32: 5 | D32: 1000000 | F32: 1000000 | H32: 1000000 | I32: Sim | J32: 1000000 | K32: Sim | L32: =VLOOKUP(B37,players!A:B,2) -> Zach Edey
A33: 3 | B33: 427 | C33: 14 | D33: 3200000 | F33: 3400000 | H33: 3600000 | I33: Sim | J33: 3900000 | K33: Sim | L33: =VLOOKUP(B38,players!A:B,2) -> Hannes Steinbach
A34: 5 | B34: 133 | C34: 6 | D34: 2800000 | F34: 3000000 | G34: Sim | H34: 3300000 | I34: Sim | L34: =VLOOKUP(B15,players!A:B,2) -> Jaylon Tyson
A35: 12 | B35: 41 | D35: 2000000 | F35: 2000000 | H35: 2000000 | L35: =VLOOKUP(B180,players!A:B,2) -> #N/A
A36: 5 | B36: 262 | C36: 2 | D36: 3600000 | F36: 3800000 | G36: Sim | H36: 4100000 | I36: Sim | L36: =VLOOKUP(B57,players!A:B,2) -> #N/A
A37: 5 | B37: 8 | C37: 11 | D37: 6000000 | F37: 6500000 | G37: Sim | L37: =VLOOKUP(B190,players!A:B,2) -> #N/A
A38: 1 | B38: 424 | C38: 15 | D38: 3800000 | F38: 4000000 | H38: 4200000 | I38: Sim | J38: 4500000 | K38: Sim | L38: =VLOOKUP(B22,players!A:B,2) -> Kaman Maluach
A39: 1 | B39: 425 | C39: 16 | D39: 3600000 | F39: 3800000 | H39: 4000000 | I39: Sim | J39: 4300000 | K39: Sim | L39: =VLOOKUP(B23,players!A:B,2) -> Jaylen Wells
A40: 1 | B40: 432 | C40: 14 | D40: 1000000 | F40: 1000000 | H40: 1000000 | I40: Sim | J40: 1000000 | K40: Sim | L40: =VLOOKUP(B20,players!A:B,2) -> Carter Bryant

Sheet picks
A1: pick_id | B1: original_team_pick_id | C1: round | D1: year | E1: current_team_owner_id
A2: P2026_R1_T07 | B2: 7 | C2: 1 | D2: 2026 | E2: 4
A3: P2026_R1_T09 | B3: 9 | C3: 1 | D3: 2026 | E3: 7
A4: P2026_R2_T07 | B4: 7 | C4: 2 | D4: 2026 | E4: 7
A5: P2028_R1_T07 | B5: 7 | C5: 1 | D5: 2028 | E5: 7
A6: P2028_R2_T07 | B6: 7 | C6: 2 | D6: 2028 | E6: 7
A7: P2029_R1_T07 | B7: 7 | C7: 1 | D7: 2029 | E7: 7
A8: P2029_R2_T07 | B8: 7 | C8: 2 | D8: 2029 | E8: 7
A9: P2026_R1_T01 | B9: 1 | C9: 1 | D9: 2026 | E9: 1
A10: P2026_R1_T11 | B10: 11 | C10: 1 | D10: 2026 | E10: 1
A11: P2026_R1_T02 | B11: 2 | C11: 1 | D11: 2026 | E11: 2
A12: P2026_R2_T01 | B12: 1 | C12: 2 | D12: 2026 | E12: 1
A13: P2026_R2_T05 | B13: 5 | C13: 2 | D13: 2026 | E13: 1
... A113: P2029_R2_T14 | B113: 14 | C113: 2 | D113: 2029 | E113: 14
